{"content": {"suites": {"0": {"status": {"total_pass": 0, "total_skip": 0, "total_xpass": 0, "total_xfail": 0, "total_rerun": 0, "total_fail": 1, "total_error": 0}, "tests": {"0": {"status": "FAIL", "message": "   socket.gaierror: [Errno 11001] getaddrinfo failed\n       urllib3.exceptions.NewConnectionError: <urllib3.connection.HTTPSConnection object at 0x000002450FF02DA0>: Failed to establish a new connection: [Errno 11001] getaddrinfo failed\n       urllib3.exceptions.MaxRetryError: HTTPSConnectionPool(host='reqres.in', port=443): Max retries exceeded with url: /api/users?page=2 (Caused by NewConnectionError('<urllib3.connection.HTTPSConnection object at 0x000002450FF02DA0>: Failed to establish a new connection: [Errno 11001] getaddrinfo failed'))\n       requests.exceptions.ConnectionError: HTTPSConnectionPool(host='reqres.in', port=443): Max retries exceeded with url: /api/users?page=2 (Caused by NewConnectionError('<urllib3.connection.HTTPSConnection object at 0x000002450FF02DA0>: Failed to establish a new connection: [Errno 11001] getaddrinfo failed'))\n", "test_name": "test_fetchUserData", "rerun": "0"}}, "suite_name": "testCases/test_fetchUserData.py"}, "1": {"suite_name": "testCases/test_getUserId.py", "tests": {"0": {"status": "FAIL", "message": "   socket.gaierror: [Errno 11001] getaddrinfo failed\n       urllib3.exceptions.NewConnectionError: <urllib3.connection.HTTPSConnection object at 0x000002450FAFC6A0>: Failed to establish a new connection: [Errno 11001] getaddrinfo failed\n       urllib3.exceptions.MaxRetryError: HTTPSConnectionPool(host='reqres.in', port=443): Max retries exceeded with url: /api/users?page=2 (Caused by NewConnectionError('<urllib3.connection.HTTPSConnection object at 0x000002450FAFC6A0>: Failed to establish a new connection: [Errno 11001] getaddrinfo failed'))\n       requests.exceptions.ConnectionError: HTTPSConnectionPool(host='reqres.in', port=443): Max retries exceeded with url: /api/users?page=2 (Caused by NewConnectionError('<urllib3.connection.HTTPSConnection object at 0x000002450FAFC6A0>: Failed to establish a new connection: [Errno 11001] getaddrinfo failed'))\n", "test_name": "test_getUserId", "rerun": "0"}}, "status": {"total_pass": 0, "total_skip": 0, "total_xpass": 0, "total_xfail": 0, "total_rerun": 0, "total_fail": 1, "total_error": 0}}}}, "date": "March 01, 2022", "start_time": 1646148908.915083, "total_suite": 2, "status": "FAIL", "status_list": {"pass": "0", "fail": "2", "skip": "0", "error": "0", "xpass": "0", "xfail": "0", "rerun": "0"}, "total_tests": "2"}